<?xml version="1.0" encoding="UTF-8"?>
<!-- Generated by org.testng.reporters.JUnitReportReporter -->
<testsuite hostname="ROHIT-PC" failures="0" tests="1" name="CareInsurance.Test.CalculatePremiumErrorMessageTest1" time="40.263" errors="1" timestamp="2024-11-18T10:03:06 IST" skipped="0">
  <testcase classname="CareInsurance.Test.CalculatePremiumErrorMessageTest1" name="calculatePremiumError" time="40.263">
    <error message="Cannot invoke &quot;java.sql.Connection.createStatement()&quot; because &quot;this.connection&quot; is null" type="java.lang.NullPointerException">
      <![CDATA[java.lang.NullPointerException: Cannot invoke "java.sql.Connection.createStatement()" because "this.connection" is null
at CareInsurance.Main.DbClass.executeQuery(DbClass.java:23)
at CareInsurance.Test.CalculatePremiumErrorMessageTest1.calculatePremiumError(CalculatePremiumErrorMessageTest1.java:98)
at java.base/jdk.internal.reflect.DirectMethodHandleAccessor.invoke(DirectMethodHandleAccessor.java:103)
at java.base/java.lang.reflect.Method.invoke(Method.java:580)
at org.testng.internal.MethodInvocationHelper.invokeMethod(MethodInvocationHelper.java:133)
at org.testng.internal.TestInvoker.invokeMethod(TestInvoker.java:598)
at org.testng.internal.TestInvoker.invokeTestMethod(TestInvoker.java:173)
at org.testng.internal.MethodRunner.runInSequence(MethodRunner.java:46)
at org.testng.internal.TestInvoker$MethodInvocationAgent.invoke(TestInvoker.java:824)
at org.testng.internal.TestInvoker.invokeTestMethods(TestInvoker.java:146)
at org.testng.internal.TestMethodWorker.invokeTestMethods(TestMethodWorker.java:146)
at org.testng.internal.TestMethodWorker.run(TestMethodWorker.java:128)
at java.base/java.util.ArrayList.forEach(ArrayList.java:1597)
at org.testng.TestRunner.privateRun(TestRunner.java:794)
at org.testng.TestRunner.run(TestRunner.java:596)
at org.testng.SuiteRunner.runTest(SuiteRunner.java:377)
at org.testng.SuiteRunner.runSequentially(SuiteRunner.java:371)
at org.testng.SuiteRunner.privateRun(SuiteRunner.java:332)
at org.testng.SuiteRunner.run(SuiteRunner.java:276)
at org.testng.SuiteRunnerWorker.runSuite(SuiteRunnerWorker.java:53)
at org.testng.SuiteRunnerWorker.run(SuiteRunnerWorker.java:96)
at org.testng.TestNG.runSuitesSequentially(TestNG.java:1212)
at org.testng.TestNG.runSuitesLocally(TestNG.java:1134)
at org.testng.TestNG.runSuites(TestNG.java:1063)
at org.testng.TestNG.run(TestNG.java:1031)
at org.testng.remote.AbstractRemoteTestNG.run(AbstractRemoteTestNG.java:115)
at org.testng.remote.RemoteTestNG.initAndRun(RemoteTestNG.java:293)
at org.testng.remote.RemoteTestNG.main(RemoteTestNG.java:91)
]]>
    </error>
  </testcase> <!-- calculatePremiumError -->
  <system-out>
    <![CDATA[random number: 6822906136
this is query: select * from lt_logotp where mobile='6822906136']]>
  </system-out>
</testsuite> <!-- CareInsurance.Test.CalculatePremiumErrorMessageTest1 -->
